### Error

- backend와 frontend에서 에러를 처리하는 방법이 궁금했다.
- 현재 프로덕트에서 backend와 frontend 코드를 모두 사용하고 있다.
- 둘다 js환경이며 typescript를 사용한다
- 하지만, api 통신 과정에서 error가 발생하고, console.error / throw new Error
  - 또는 frontend에선 next.js를 사용하는데, 서버컴포넌트와 client 컴포넌트의 에러처리는 어떻게 해줘야할까?
  - client 컴포넌트는 tanstack-query를 사용하는데, 이때 [비동기 에러 처리를 React-Errorboundary로는 처리할 수 없기때문이다.](https://tkdodo.eu/blog/react-query-error-handling#error-boundaries)

<br>

- 베스트한 방법은 뭘까?

### 먼저 useQuery부터

[React Query Error Handling](https://tkdodo.eu/blog/react-query-error-handling#error-boundaries)
[Breaking React Query's API on purpose](https://tkdodo.eu/blog/breaking-react-querys-api-on-purpose)

- 이 두 글부터 다시 읽고 하나씩 적용해보자
- 근데, 그 전에 ErrorBoundary를 적용해주었다.

<br>

- record를 가져오는 도중 에러가 발생했다고 가정해보자.

  - 그럼 error를 서버쪽에서 전달해주면 프론트에선 보여주는 역할을 해야하는걸까?
  - 프론트에서 별도의 처리를 필요하지 않은가?

- 먼저 client 에러 처리부터 해보자

  - suspense / error boundary로 처리해보자
  -

- 에러 분기 처리 이후에 재요청은 react-query를 통해서 작성하면 되는 듯 하다

<br>

### meta tag vs error

```TSX
const getMessage = async (
  userEmail: string | null | undefined,
  token: string | undefined,
) => {
  const encodedEmail = encodeURIComponent(userEmail || '');
  const res = await fetch(
    `${process.env.NEXT_PUBLIC_SERVER_URL}/api/record/${encodedEmail}`,
    {
      method: 'GET',
      headers: {
        authorization: `Bearer ${token}`,
      },
    },
  );

  if (!res.ok) {
    throw new Error(
      'useRecordGetQuery.ts: 서버에서 데이터를 가져오는데 실패했습니다.',
    );
  }

  return res.json();
};

export const useRecordGetQuery = (
  userEmail: string | null | undefined,
  token: string | undefined,
) => {
  const { data: messages = [] } = useQuery(
    [...recordManagerKeys.record, userEmail],
    () => getMessage(userEmail, token),
    {
      meta: {
        errorMessage: '이게 있다면 실패한 에러가 작성되겠죠.',
      },
      enabled: !!userEmail,
      select: (data: Message[]) => data.map(decodeMessages),
    },
  );

  return {
    messages,
  };
};
```

- 위와 같이 작성된 코드가 있다.

<br>

```TSX
export const createQueryClient = new QueryClient({
  queryCache: new QueryCache({
    onError: (error, query) => {
      console.log('여기는 queryClient입니다.', error);
      if (query.meta?.errorMessage) {
        console.log('여기는 if query meta 안입니다.');
        throw new Error(query.meta?.errorMessage as any);
      }

      throw new Error(error as any);
    },
  }),

  mutationCache: new MutationCache({
    onError: (error, _variables, _context, mutation) => {
      if (mutation.options.onError) {
        throw new Error(error as any);
        return;
      }

      throw new Error(error as any);
    },
  }),
});
```

- 그리고 queryClient에선 다음과 같이 작성되어있다고 가정해보자.
- 여기서 meta로 error를 처리하면 if문 내에 있는 코드가 실행된다.
- 즉, query별로 따로 에러를 분기처리하고 싶을 경우에 작성하는 듯 하다. [Defining on-demand messages](https://tkdodo.eu/blog/breaking-react-querys-api-on-purpose#defining-on-demand-messages)
- 하지만 나의 경우 따로 작성하기보단, throw 한 에러를 전역으로 받아주고 싶었다.
  - 이러기 위해 meta tag는 별도로 필요하지 않다.

<br>

- onError의 경우엔 화면별로 다르게 처리해야하는 케이스가 존재할 경우 사용하는 듯 하다.
  - 이 경우를 위해 meta error 처리가 필요한 것, 왜냐하면 onError는 삭제될 예정이기 때문이다.

```TSX
const getMessage = async (
  userEmail: string | null | undefined,
  token: string | undefined,
) => {
  try {
    const encodedEmail = encodeURIComponent(userEmail || '');
    const res = await fetch(
      `${process.env.NEXT_PUBLIC_SERVER_URL}/api/record/${encodedEmail}`,
      {
        method: 'GET',
        headers: {
          authorization: `Bearer ${token}`,
        },
      },
    );

    if (!res.ok) {
      throw new Error(
        'useRecordGetQuery.ts: 서버에서 데이터를 가져오는데 실패했습니다.',
      );
    }

    return res.json();
  } catch (error) {
    console.log(
      '여기는 언제 실행되는 걸까요?, useQuery hooks 내의 try / catch',
    );
    console.error(error);
  }
};

export const useRecordGetQuery = (
  userEmail: string | null | undefined,
  token: string | undefined,
) => {
  const { data: messages = [] } = useQuery(
    [...recordManagerKeys.record, userEmail],
    () => getMessage(userEmail, token),
    {
      enabled: !!userEmail,
      select: (data: Message[]) => data.map(decodeMessages),
    },
  );


  return {
    messages,
  };
};

```

- 위의 경우는 getMessage에서 try ... catch로 감싸줬다. 이때 에러가 터지지 않는다. log만 찍힌다.
- 하지만, 이럴 경우 에러가 터졌는지 알 수가 없다. 터지는게 에러가

<br>

- 정리해보면, 유저와 개발자로 각각 나눠줄 수 있을 것 같음
  - 유저에게는 toast UI로 표출해주고, 되돌아가거나, re-try같은 버튼을 제공
  - 개발자에겐 console.error로 로그를 남겨준다.

<br>
